<?xml version="1.0" encoding="utf-8"?>
<robot name="spot_arm">

    <link name="b0">
      <visual>
        <geometry>
          <mesh filename="package://my_spot/description/meshes/B0.dae" />
        </geometry>
      </visual>
      <collision>
	<geometry>
	  <mesh filename="package://my_spot/description/meshes/B0.stl"/>
	</geometry>
      </collision>
    </link>

    <link name="base">
      <visual>
        <geometry>
          <mesh filename="package://my_spot/description/meshes/Base.dae" />
        </geometry>
      </visual>
      <collision>
	<geometry>
	  <mesh filename="package://my_spot/description/meshes/Base.stl"/>
	</geometry>
      </collision>
    </link>

    <link name="part1">
      <collision>
	<geometry>
	  <mesh filename="package://my_spot/description/meshes/Part1.stl"/>
	</geometry>
      </collision>
    </link>

   <link name="part2">
      <visual>
        <geometry>
          <mesh filename="package://my_spot/description/meshes/Part2.dae" />
        </geometry>
      </visual>
      <collision>
	<geometry>
	  <mesh filename="package://my_spot/description/meshes/Part2.stl"/>
	</geometry>
      </collision>
    </link>

   <link name="part3">
      <visual>
        <geometry>
          <mesh filename="package://my_spot/description/meshes/Part3.dae" />
        </geometry>
      </visual>
      <collision>
	<geometry>
	  <mesh filename="package://my_spot/description/meshes/Part3.stl"/>
	</geometry>
      </collision>
    </link>

   <link name="part4">
      <visual>
        <geometry>
          <mesh filename="package://my_spot/description/meshes/Part4.dae" />
        </geometry>
      </visual>
      <collision>
	<geometry>
	  <mesh filename="package://my_spot/description/meshes/Part4.stl"/>
	</geometry>
      </collision>
    </link>

   <link name="gripper">
      <visual>
        <geometry>
          <mesh filename="package://my_spot/description/meshes/Gripper.dae" />
        </geometry>
      </visual>
      <collision>
	<geometry>
	  <mesh filename="package://my_spot/description/meshes/Gripper.stl"/>
	</geometry>
      </collision>
    </link>

   <link name="finger">
      <visual>
        <geometry>
          <mesh filename="package://my_spot/description/meshes/Finger.dae" />
        </geometry>
      </visual>
      <collision>
	<geometry>
	  <mesh filename="package://my_spot/description/meshes/Finger.stl"/>
	</geometry>
      </collision>
    </link>

    <joint name="b0_to_base" type="revolute">
      <parent link="b0"/>
      <child link="base"/>
      <axis xyz="0 0 1" />
      <origin xyz="0.0 0.0 0.047" rpy="0 0 0" />
      <limit effort="900" velocity="900.00" lower="-2.61799" upper="3.14159"/>
    </joint>

    <joint name="base_to_upper_arm" type="revolute">
      <parent link="base"/>
      <child link="part1"/>
      <axis xyz="0 0 1" />
      <origin xyz="0.0 0.0 0.065" rpy="0 -1.5708 0" />
      <limit effort="900" velocity="900.00" lower="-3.14159" upper="0.523599"/>
    </joint>

    <joint name="upper_arm_to_shoulder" type="revolute">
      <parent link="part1"/>
      <child link="part2"/>
      <axis xyz="0 0 1" />
      <origin xyz="0.0 0.34 0.0" rpy="0 0 0" />
      <limit effort="900" velocity="900.00" lower="0.0" upper="3.14159"/>
    </joint>

    <joint name="shoulder_to_forearm" type="revolute">
      <parent link="part2"/>
      <child link="part3"/>
      <axis xyz="0 0 1" />
      <origin xyz="0.132 0.083 0.0" rpy="0 1.5708 0" />
      <limit effort="900" velocity="900.00" lower="-2.79253" upper="2.79253"/>
    </joint>

    <joint name="forearm_to_wrist" type="revolute">
      <parent link="part3"/>
      <child link="part4"/>
      <axis xyz="0 0 1" />
      <origin xyz="-0.05 0.0 0.26" rpy="0 -1.5708 0" />
      <limit effort="900" velocity="900.00" lower="-1.8326" upper="1.8326"/>
    </joint>

    <joint name="wrist_to_gripper" type="revolute">
      <parent link="part4"/>
      <child link="gripper"/>
      <axis xyz="0 0 1" />
      <origin xyz="0.07 0.0 -0.05" rpy="0 1.5708 0" />
      <limit effort="900" velocity="900.00" lower="-2.87979" upper="2.87979"/>
    </joint>

    <joint name="gripper_to_finger" type="revolute">
      <parent link="gripper"/>
      <child link="finger"/>
      <axis xyz="0 0 1" />
      <origin xyz="0.19557 0.0 0.0" rpy="-1.5708 0 0" />
      <limit effort="900" velocity="900.00" lower="-1.5708" upper="0.0"/>
    </joint>

</robot>
